Workbook

Sheet Global
A1: Proveedor | B1: Codigo_ML | C1: SKU | D1: Titulo | E1: Status | F1: Stock_FULL | G1: Stock_FLEX | H1: Stock_Total | I1: Supermarket | J1: Costo | K1: Valorización | L1: V30D | M1: V30FULL | N1: V30FLEX | O1: V30CENTRO | P1: RepFULL | Q1: RepFLEX | R1: RepTotal | S1: Permalink
A2: {=XLOOKUP(B2,Costos_Proveedores!$B$2:$B$2000,Costos_Proveedores!$A$2:$A$2000)} -> MULI | B2: MLC2853724594 | D2: Espejo Para Maquillaje Espejo Doble De Mesa Con Aumento 36cm | E2: closed | F2: 1 | G2: 1 | H2: =IF(I2="Sí",F2,F2+G2) -> 2 | I2: No | J2: =VLOOKUP(B2,Costos_Proveedores!$B$2:$J$1000,9,FALSE()) -> 4550 | K2: =IFERROR(H2*J2,0) -> 9100 | P2: =IF(M2>=F2,M2-F2,0) -> 0 | Q2: =IF(N2+O2-G2>=0,N2+O2-G2,0) -> 0 | R2: =P2+Q2 -> 0 | S2: https://articulo.mercadolibre.cl/MLC-2853724594-espejo-para-maquillaje-espejo-doble-de-mesa-con-aumento-36cm-_JM
A3: {=XLOOKUP(B3,Costos_Proveedores!$B$2:$B$2000,Costos_Proveedores!$A$2:$A$2000)} -> MULI | B3: MLC1604270301 | C3: ML272 | D3: Organizador Y Separador De Cubiertos | E3: closed | F3: 0 | G3: 0 | H3: =IF(I3="Sí",F3,F3+G3) -> 0 | I3: No | J3: =VLOOKUP(B3,Costos_Proveedores!$B$2:$J$1000,9,FALSE()) -> 1848 | K3: =IFERROR(H3*J3,0) -> 0 | L3: =SUM(M3:O3) -> 39 | M3: 39 | N3: 0 | O3: 0 | P3: =IF(M3>=F3,M3-F3,0) -> 39 | Q3: =IF(N3+O3-G3>=0,N3+O3-G3,0) -> 0 | R3: =P3+Q3 -> 39 | S3: https://articulo.mercadolibre.cl/MLC-1604270301-organizador-y-separador-de-cubiertos-_JM
A4: {=XLOOKUP(B4,Costos_Proveedores!$B$2:$B$2000,Costos_Proveedores!$A$2:$A$2000)} -> MULI | B4: MLC1582676309 | C4: ML247 | D4: Tabla Planchar Tabla De Planchar Metal Y Tela 110 Cm Mangas Al Azar Multicolor | E4: paused | G4: 0 | H4: =IF(I4="Sí",F4,F4+G4) -> 0 | I4: No | J4: =VLOOKUP(B4,Costos_Proveedores!$B$2:$J$1000,9,FALSE()) -> 14400 | K4: =IFERROR(H4*J4,0) -> 0 | P4: =IF(M4>=F4,M4-F4,0) -> 0 | Q4: =IF(N4+O4-G4>=0,N4+O4-G4,0) -> 0 | R4: =P4+Q4 -> 0 | S4: https://articulo.mercadolibre.cl/MLC-1582676309-tabla-planchar-tabla-de-planchar-metal-y-tela-110-cm-mangas-al-azar-multicolor-_JM
A5: {=XLOOKUP(B5,Costos_Proveedores!$B$2:$B$2000,Costos_Proveedores!$A$2:$A$2000)} -> MULI | B5: MLC1582663459 | C5: ML256 | D5: Organizador Verdulero Frutero 3 Niveles Metálico Inoxidable Plateado | E5: paused | G5: 0 | H5: =IF(I5="Sí",F5,F5+G5) -> 0 | I5: No | J5: =VLOOKUP(B5,Costos_Proveedores!$B$2:$J$1000,9,FALSE()) -> 10080 | K5: =IFERROR(H5*J5,0) -> 0 | P5: =IF(M5>=F5,M5-F5,0) -> 0 | Q5: =IF(N5+O5-G5>=0,N5+O5-G5,0) -> 0 | R5: =P5+Q5 -> 0 | S5: https://articulo.mercadolibre.cl/MLC-1582663459-organizador-verdulero-frutero-3-niveles-metalico-inoxidable-plateado-_JM
A6: {=XLOOKUP(B6,Costos_Proveedores!$B$2:$B$2000,Costos_Proveedores!$A$2:$A$2000)} -> MULI | B6: MLC1582589593 | C6: WF33322 | D6: Fuente Pileta Cascada De Agua Jesus Grande 39 Cm Con Luz Gris | E6: paused | G6: 0 | H6: =IF(I6="Sí",F6,F6+G6) -> 0 | I6: No | J6: =VLOOKUP(B6,Costos_Proveedores!$B$2:$J$1000,9,FALSE()) -> 16800 | K6: =IFERROR(H6*J6,0) -> 0 | P6: =IF(M6>=F6,M6-F6,0) -> 0 | Q6: =IF(N6+O6-G6>=0,N6+O6-G6,0) -> 0 | R6: =P6+Q6 -> 0 | S6: https://articulo.mercadolibre.cl/MLC-1582589593-fuente-pileta-cascada-de-agua-jesus-grande-39-cm-con-luz-gris-_JM
A7: {=XLOOKUP(B7,Costos_Proveedores!$B$2:$B$2000,Costos_Proveedores!$A$2:$A$2000)} -> MULI | B7: MLC1582563757 | C7: WF33313 | D7: Fuente Pileta Cascada De Agua Querubín Con Luz Grande 28cm Gris | E7: paused | G7: 0 | H7: =IF(I7="Sí",F7,F7+G7) -> 0 | I7: No | J7: =VLOOKUP(B7,Costos_Proveedores!$B$2:$J$1000,9,FALSE()) -> 12800 | K7: =IFERROR(H7*J7,0) -> 0 | P7: =IF(M7>=F7,M7-F7,0) -> 0 | Q7: =IF(N7+O7-G7>=0,N7+O7-G7,0) -> 0 | R7: =P7+Q7 -> 0 | S7: https://articulo.mercadolibre.cl/MLC-1582563757-fuente-pileta-cascada-de-agua-querubin-con-luz-grande-28cm-gris-_JM
A8: {=XLOOKUP(B8,Costos_Proveedores!$B$2:$B$2000,Costos_Proveedores!$A$2:$A$2000)} -> MULI | B8: MLC1582563657 | C8: 104922 | D8: Pack 4 Vasos Con Bombilla Y Tapa 600 Ml Vidrio Shopero 600ml Multicolor | E8: active | G8: 2 | H8: =IF(I8="Sí",F8,F8+G8) -> 2 | I8: No | J8: =VLOOKUP(B8,Costos_Proveedores!$B$2:$J$1000,9,FALSE()) -> 4032 | K8: =IFERROR(H8*J8,0) -> 8064 | L8: 5 | M8: 0 | N8: 0 | O8: 5 | P8: =IF(M8>=F8,M8-F8,0) -> 0 | Q8: =IF(N8+O8-G8>=0,N8+O8-G8,0) -> 3 | R8: =P8+Q8 -> 3 | S8: https://articulo.mercadolibre.cl/MLC-1582563657-pack-4-vasos-con-bombilla-y-tapa-600-ml-vidrio-shopero-600ml-multicolor-_JM
A9: {=XLOOKUP(B9,Costos_Proveedores!$B$2:$B$2000,Costos_Proveedores!$A$2:$A$2000)} -> MULI | B9: MLC1582511883 | C9: 45100 | D9: Pack 6 Platos Hondos Floreado Opal Templado 22cm Blanco | E9: paused | G9: 0 | H9: =IF(I9="Sí",F9,F9+G9) -> 0 | I9: No | J9: =VLOOKUP(B9,Costos_Proveedores!$B$2:$J$1000,9,FALSE()) -> 6852 | K9: =IFERROR(H9*J9,0) -> 0 | P9: =IF(M9>=F9,M9-F9,0) -> 0 | Q9: =IF(N9+O9-G9>=0,N9+O9-G9,0) -> 0 | R9: =P9+Q9 -> 0 | S9: https://articulo.mercadolibre.cl/MLC-1582511883-pack-6-platos-hondos-floreado-opal-templado-22cm-blanco-_JM
A10: {=XLOOKUP(B10,Costos_Proveedores!$B$2:$B$2000,Costos_Proveedores!$A$2:$A$2000)} -> MULI | B10: MLC3092101060 | C10: 108484 | D10: Pack 6 Piso Deportivo Modular Goma Eva 60x60x1 Cm Fitness Blanco Blanco Industrial | E10: paused | F10: 0 | G10: 0 | H10: =IF(I10="Sí",F10,F10+G10) -> 0 | I10: No | J10: =VLOOKUP(B10,Costos_Proveedores!$B$2:$J$1000,9,FALSE()) -> 8400 | K10: =IFERROR(H10*J10,0) -> 0 | P10: =IF(M10>=F10,M10-F10,0) -> 0 | Q10: =IF(N10+O10-G10>=0,N10+O10-G10,0) -> 0 | R10: =P10+Q10 -> 0 | S10: https://articulo.mercadolibre.cl/MLC-3092101060-pack-6-piso-deportivo-modular-goma-eva-60x60x1-cm-fitness-blanco-blanco-industrial-_JM
A11: {=XLOOKUP(B11,Costos_Proveedores!$B$2:$B$2000,Costos_Proveedores!$A$2:$A$2000)} -> MULI | B11: MLC3092101058 | C11: 108483 | D11: Pack 6 Piso Deportivo Modular Goma Eva 60x60x1 Cm Fitness Negro Negro Industrial | E11: paused | F11: 0 | G11: 0 | H11: =IF(I11="Sí",F11,F11+G11) -> 0 | I11: No | J11: =VLOOKUP(B11,Costos_Proveedores!$B$2:$J$1000,9,FALSE()) -> 8400 | K11: =IFERROR(H11*J11,0) -> 0 | L11: 31 | M11: 31 | N11: 0 | O11: 0 | P11: =IF(M11>=F11,M11-F11,0) -> 31 | Q11: =IF(N11+O11-G11>=0,N11+O11-G11,0) -> 0 | R11: =P11+Q11 -> 31 | S11: https://articulo.mercadolibre.cl/MLC-3092101058-pack-6-piso-deportivo-modular-goma-eva-60x60x1-cm-fitness-negro-negro-industrial-_JM
A12: {=XLOOKUP(B12,Costos_Proveedores!$B$2:$B$2000,Costos_Proveedores!$A$2:$A$2000)} -> MULI | B12: MLC2933761314 | C12: 106551G | D12: Basurero Metálico Con Pedal 8 Litros Pedal Acabado Madera Gris | E12: paused | F12: 0 | G12: 0 | H12: =IF(I12="Sí",F12,F12+G12) -> 0 | I12: No | J12: =VLOOKUP(B12,Costos_Proveedores!$B$2:$J$1000,9,FALSE()) -> 8400 | K12: =IFERROR(H12*J12,0) -> 0 | P12: =IF(M12>=F12,M12-F12,0) -> 0 | Q12: =IF(N12+O12-G12>=0,N12+O12-G12,0) -> 0 | R12: =P12+Q12 -> 0 | S12: https://articulo.mercadolibre.cl/MLC-2933761314-basurero-metalico-con-pedal-8-litros-pedal-acabado-madera-gris-_JM
A13: {=XLOOKUP(B13,Costos_Proveedores!$B$2:$B$2000,Costos_Proveedores!$A$2:$A$2000)} -> MULI | B13: MLC2933761312 | C13: 106551C | D13: Basurero Metálico Con Pedal 8 Litros Pedal Acabado Madera Marrón | E13: paused | F13: 0 | G13: 0 | H13: =IF(I13="Sí",F13,F13+G13) -> 0 | I13: No | J13: =VLOOKUP(B13,Costos_Proveedores!$B$2:$J$1000,9,FALSE()) -> 8400 | K13: =IFERROR(H13*J13,0) -> 0 | L13: 7 | M13: 7 | N13: 0 | O13: 0 | P13: =IF(M13>=F13,M13-F13,0) -> 7 | Q13: =IF(N13+O13-G13>=0,N13+O13-G13,0) -> 0 | R13: =P13+Q13 -> 7 | S13: https://articulo.mercadolibre.cl/MLC-2933761312-basurero-metalico-con-pedal-8-litros-pedal-acabado-madera-marron-_JM
A14: {=XLOOKUP(B14,Costos_Proveedores!$B$2:$B$2000,Costos_Proveedores!$A$2:$A$2000)} -> MULI | B14: MLC2863704914 | C14: 107180 | D14: Pack 4 Goma Eva Piso Alfombra Antigolpes 60x60x1cm Madera Marrón Piso Flotante | E14: paused | F14: 0 | G14: 15 | H14: =IF(I14="Sí",F14,F14+G14) -> 15 | I14: No | J14: =VLOOKUP(B14,Costos_Proveedores!$B$2:$J$1000,9,FALSE()) -> 5880 | K14: =IFERROR(H14*J14,0) -> 88200 | P14: =IF(M14>=F14,M14-F14,0) -> 0 | Q14: =IF(N14+O14-G14>=0,N14+O14-G14,0) -> 0 | R14: =P14+Q14 -> 0 | S14: https://articulo.mercadolibre.cl/MLC-2863704914-pack-4-goma-eva-piso-alfombra-antigolpes-60x60x1cm-madera-marron-piso-flotante-_JM
A15: {=XLOOKUP(B15,Costos_Proveedores!$B$2:$B$2000,Costos_Proveedores!$A$2:$A$2000)} -> MULI | B15: MLC2863704912 | C15: 107179 | D15: Pack 4 Goma Eva Piso Alfombra Antigolpes 60x60x1cm Madera Beige Lisa | E15: paused | F15: 0 | G15: 0 | H15: =IF(I15="Sí",F15,F15+G15) -> 0 | I15: No | J15: =VLOOKUP(B15,Costos_Proveedores!$B$2:$J$1000,9,FALSE()) -> 6720 | K15: =IFERROR(H15*J15,0) -> 0 | P15: =IF(M15>=F15,M15-F15,0) -> 0 | Q15: =IF(N15+O15-G15>=0,N15+O15-G15,0) -> 0 | R15: =P15+Q15 -> 0 | S15: https://articulo.mercadolibre.cl/MLC-2863704912-pack-4-goma-eva-piso-alfombra-antigolpes-60x60x1cm-madera-beige-lisa-_JM
A16: {=XLOOKUP(B16,Costos_Proveedores!$B$2:$B$2000,Costos_Proveedores!$A$2:$A$2000)} -> MULI | B16: MLC2853425396 | C16: 107833 | D16: Basurero Metálico Con Pedal 12 Litros Plateado Acero Canasta Gris | E16: paused | F16: 0 | G16: 12 | H16: =IF(I16="Sí",F16,F16+G16) -> 12 | I16: No | J16: =VLOOKUP(B16,Costos_Proveedores!$B$2:$J$1000,9,FALSE()) -> 8400 | K16: =IFERROR(H16*J16,0) -> 100800 | L16: 56 | M16: 56 | N16: 0 | O16: 0 | P16: =IF(M16>=F16,M16-F16,0) -> 56 | Q16: =IF(N16+O16-G16>=0,N16+O16-G16,0) -> 0 | R16: =P16+Q16 -> 56 | S16: https://articulo.mercadolibre.cl/MLC-2853425396-basurero-metalico-con-pedal-12-litros-plateado-acero-canasta-gris-_JM
A17: {=XLOOKUP(B17,Costos_Proveedores!$B$2:$B$2000,Costos_Proveedores!$A$2:$A$2000)} -> MULI | B17: MLC2853290088 | C17: 788133 | D17: Pack 24 Burbujas Juguete Sorpresa Cumpleaños Regalo Paseo Multicolor | E17: paused | F17: 0 | G17: 0 | H17: =IF(I17="Sí",F17,F17+G17) -> 0 | I17: No | J17: =VLOOKUP(B17,Costos_Proveedores!$B$2:$J$1000,9,FALSE()) -> 4200 | K17: =IFERROR(H17*J17,0) -> 0 | P17: =IF(M17>=F17,M17-F17,0) -> 0 | Q17: =IF(N17+O17-G17>=0,N17+O17-G17,0) -> 0 | R17: =P17+Q17 -> 0 | S17: https://articulo.mercadolibre.cl/MLC-2853290088-pack-24-burbujas-juguete-sorpresa-cumpleanos-regalo-paseo-multicolor-_JM
A18: {=XLOOKUP(B18,Costos_Proveedores!$B$2:$B$2000,Costos_Proveedores!$A$2:$A$2000)} -> MULI | B18: MLC2853171858 | D18: Set 10 30x30 Alfombra Infantil Goma Eva Cuadros Bebes Niños | E18: paused | H18: =IF(I18="Sí",F18,F18+G18) -> 0 | I18: No | J18: =VLOOKUP(B18,Costos_Proveedores!$B$2:$J$1000,9,FALSE()) -> 2730 | K18: =IFERROR(H18*J18,0) -> 0 | P18: =IF(M18>=F18,M18-F18,0) -> 0 | Q18: =IF(N18+O18-G18>=0,N18+O18-G18,0) -> 0 | R18: =P18+Q18 -> 0 | S18: https://articulo.mercadolibre.cl/MLC-2853171858-set-10-30x30-alfombra-infantil-goma-eva-cuadros-bebes-ninos-_JM
A19: {=XLOOKUP(B19,Costos_Proveedores!$B$2:$B$2000,Costos_Proveedores!$A$2:$A$2000)} -> MULI | B19: MLC1583375395 | C19: 103366 | D19: Basurero Metálico Con Pedal 3 Litros Plateado Acero Canasta Gris | E19: paused | F19: 0 | G19: 0 | H19: =IF(I19="Sí",F19,F19+G19) -> 0 | I19: No | J19: =VLOOKUP(B19,Costos_Proveedores!$B$2:$J$1000,9,FALSE()) -> 3780 | K19: =IFERROR(H19*J19,0) -> 0 | P19: =IF(M19>=F19,M19-F19,0) -> 0 | Q19: =IF(N19+O19-G19>=0,N19+O19-G19,0) -> 0 | R19: =P19+Q19 -> 0 | S19: https://articulo.mercadolibre.cl/MLC-1583375395-basurero-metalico-con-pedal-3-litros-plateado-acero-canasta-gris-_JM
A20: {=XLOOKUP(B20,Costos_Proveedores!$B$2:$B$2000,Costos_Proveedores!$A$2:$A$2000)} -> MULI | B20: MLC1583337113 | C20: 103368 | D20: Basurero Metálico Con Pedal 8 Litros Plateado Acero Canasta | E20: paused | F20: 0 | G20: 0 | H20: =IF(I20="Sí",F20,F20+G20) -> 0 | I20: No | J20: =VLOOKUP(B20,Costos_Proveedores!$B$2:$J$1000,9,FALSE()) -> 6720 | K20: =IFERROR(H20*J20,0) -> 0 | P20: =IF(M20>=F20,M20-F20,0) -> 0 | Q20: =IF(N20+O20-G20>=0,N20+O20-G20,0) -> 0 | R20: =P20+Q20 -> 0 | S20: https://articulo.mercadolibre.cl/MLC-1583337113-basurero-metalico-con-pedal-8-litros-plateado-acero-canasta-_JM
A21: {=XLOOKUP(B21,Costos_Proveedores!$B$2:$B$2000,Costos_Proveedores!$A$2:$A$2000)} -> MULI | B21: MLC1583327473 | C21: 103370 | D21: Basurero Metálico Con Pedal 20 Litros Plateado Acero Canasta Acero Inox Brillante | E21: active | F21: 25 | G21: 0 | H21: =IF(I21="Sí",F21,F21+G21) -> 25 | I21: No | J21: =VLOOKUP(B21,Costos_Proveedores!$B$2:$J$1000,9,FALSE()) -> 11760 | K21: =IFERROR(H21*J21,0) -> 294000 | L21: 30 | M21: 31 | N21: 0 | O21: 0 | P21: =IF(M21>=F21,M21-F21,0) -> 6 | Q21: =IF(N21+O21-G21>=0,N21+O21-G21,0) -> 0 | R21: =P21+Q21 -> 6 | S21: https://articulo.mercadolibre.cl/MLC-1583327473-basurero-metalico-con-pedal-20-litros-plateado-acero-canasta-acero-inox-brillante-_JM
A22: {=XLOOKUP(B22,Costos_Proveedores!$B$2:$B$2000,Costos_Proveedores!$A$2:$A$2000)} -> MULI | B22: MLC3086615012 | C22: 107583B | D22: Espejo Para Maquillaje Espejo Doble De Mesa Con Aumento 36cm Blanco | E22: active | F22: 2 | G22: 0 | H22: =IF(I22="Sí",F22,F22+G22) -> 2 | I22: No | J22: =VLOOKUP(B22,Costos_Proveedores!$B$2:$J$1000,9,FALSE()) -> 4550 | K22: =IFERROR(H22*J22,0) -> 9100 | L22: 2 | M22: 2 | N22: 0 | O22: 0 | P22: =IF(M22>=F22,M22-F22,0) -> 0 | Q22: =IF(N22+O22-G22>=0,N22+O22-G22,0) -> 0 | R22: =P22+Q22 -> 0 | S22: https://articulo.mercadolibre.cl/MLC-3086615012-espejo-para-maquillaje-espejo-doble-de-mesa-con-aumento-36cm-blanco-_JM
A23: {=XLOOKUP(B23,Costos_Proveedores!$B$2:$B$2000,Costos_Proveedores!$A$2:$A$2000)} -> MULI | B23: MLC3086615010 | C23: 107583R | D23: Espejo Para Maquillaje Espejo Doble De Mesa Con Aumento 36cm Rosado | E23: paused | F23: 0 | G23: 6 | H23: =IF(I23="Sí",F23,F23+G23) -> 6 | I23: No | J23: =VLOOKUP(B23,Costos_Proveedores!$B$2:$J$1000,9,FALSE()) -> 4550 | K23: =IFERROR(H23*J23,0) -> 27300 | L23: 1 | M23: 1 | N23: 0 | O23: 0 | P23: =IF(M23>=F23,M23-F23,0) -> 1 | Q23: =IF(N23+O23-G23>=0,N23+O23-G23,0) -> 0 | R23: =P23+Q23 -> 1 | S23: https://articulo.mercadolibre.cl/MLC-3086615010-espejo-para-maquillaje-espejo-doble-de-mesa-con-aumento-36cm-rosado-_JM
A24: {=XLOOKUP(B24,Costos_Proveedores!$B$2:$B$2000,Costos_Proveedores!$A$2:$A$2000)} -> MULI | B24: MLC2853699866 | C24: NE6511 | D24: Reloj De Cocina Análogo Grande Dorado Reloj De Pared 60cm Dorado Blanco | E24: paused | F24: 0 | G24: 0 | H24: =IF(I24="Sí",F24,F24+G24) -> 0 | I24: No | J24: =VLOOKUP(B24,Costos_Proveedores!$B$2:$J$1000,9,FALSE()) -> 6720 | K24: =IFERROR(H24*J24,0) -> 0 | P24: =IF(M24>=F24,M24-F24,0) -> 0 | Q24: =IF(N24+O24-G24>=0,N24+O24-G24,0) -> 0 | R24: =P24+Q24 -> 0 | S24: https://articulo.mercadolibre.cl/MLC-2853699866-reloj-de-cocina-analogo-grande-dorado-reloj-de-pared-60cm-dorado-blanco-_JM
A25: {=XLOOKUP(B25,Costos_Proveedores!$B$2:$B$2000,Costos_Proveedores!$A$2:$A$2000)} -> MULI | B25: MLC1583743561 | C25: WF33356 | D25: Pileta Y Cascada De Agua Buda Meditación Feng Shui Con Luz Gris | E25: paused | G25: 0 | H25: =IF(I25="Sí",F25,F25+G25) -> 0 | I25: No | J25: =VLOOKUP(B25,Costos_Proveedores!$B$2:$J$1000,9,FALSE()) -> 12600 | K25: =IFERROR(H25*J25,0) -> 0 | P25: =IF(M25>=F25,M25-F25,0) -> 0 | Q25: =IF(N25+O25-G25>=0,N25+O25-G25,0) -> 0 | R25: =P25+Q25 -> 0 | S25: https://articulo.mercadolibre.cl/MLC-1583743561-pileta-y-cascada-de-agua-buda-meditacion-feng-shui-con-luz-gris-_JM
A26: {=XLOOKUP(B26,Costos_Proveedores!$B$2:$B$2000,Costos_Proveedores!$A$2:$A$2000)} -> MULI | B26: MLC2855683304 | C26: LB404002 | D26: Set 4 Libros Para Colorear Antiestrés 64 Paginas Extraibles | E26: active | F26: 5 | G26: 12 | H26: =IF(I26="Sí",F26,F26+G26) -> 17 | I26: No | J26: =VLOOKUP(B26,Costos_Proveedores!$B$2:$J$1000,9,FALSE()) -> 6720 | K26: =IFERROR(H26*J26,0) -> 114240 | L26: 6 | M26: 4 | N26: 2 | O26: 0 | P26: =IF(M26>=F26,M26-F26,0) -> 0 | Q26: =IF(N26+O26-G26>=0,N26+O26-G26,0) -> 0 | R26: =P26+Q26 -> 0 | S26: https://articulo.mercadolibre.cl/MLC-2855683304-set-4-libros-para-colorear-antiestres-64-paginas-extraibles-_JM
A27: {=XLOOKUP(B27,Costos_Proveedores!$B$2:$B$2000,Costos_Proveedores!$A$2:$A$2000)} -> MULI | B27: MLC2855681612 | C27: 105738 | D27: Set Jarra Y 6 Vasos Conjunto Jarra 2 Litros Y 6 Vasos Vidrio Transparente | E27: paused | G27: 0 | H27: =IF(I27="Sí",F27,F27+G27) -> 0 | I27: No | J27: =VLOOKUP(B27,Costos_Proveedores!$B$2:$J$1000,9,FALSE()) -> 7560 | K27: =IFERROR(H27*J27,0) -> 0 | P27: =IF(M27>=F27,M27-F27,0) -> 0 | Q27: =IF(N27+O27-G27>=0,N27+O27-G27,0) -> 0 | R27: =P27+Q27 -> 0 | S27: https://articulo.mercadolibre.cl/MLC-2855681612-set-jarra-y-6-vasos-conjunto-jarra-2-litros-y-6-vasos-vidrio-transparente-_JM
A28: {=XLOOKUP(B28,Costos_Proveedores!$B$2:$B$2000,Costos_Proveedores!$A$2:$A$2000)} -> MULI | B28: MLC2855651866 | C28: 107427 | D28: 28cm Portacupcake Porta Torta Porta Cupcakes Campana Vidrio Transparente | E28: paused | F28: 0 | G28: 0 | H28: =IF(I28="Sí",F28,F28+G28) -> 0 | I28: No | J28: =VLOOKUP(B28,Costos_Proveedores!$B$2:$J$1000,9,FALSE()) -> 5880 | K28: =IFERROR(H28*J28,0) -> 0 | P28: =IF(M28>=F28,M28-F28,0) -> 0 | Q28: =IF(N28+O28-G28>=0,N28+O28-G28,0) -> 0 | R28: =P28+Q28 -> 0 | S28: https://articulo.mercadolibre.cl/MLC-2855651866-28cm-portacupcake-porta-torta-porta-cupcakes-campana-vidrio-transparente-_JM
A29: {=XLOOKUP(B29,Costos_Proveedores!$B$2:$B$2000,Costos_Proveedores!$A$2:$A$2000)} -> MULI | B29: MLC2855615494 | C29: WF33333 | D29: Fuente De Agua Pileta De Agua Buda Feng Shui 18 Cm Con Luz Gris | E29: paused | F29: 0 | G29: 0 | H29: =IF(I29="Sí",F29,F29+G29) -> 0 | I29: No | J29: =VLOOKUP(B29,Costos_Proveedores!$B$2:$J$1000,9,FALSE()) -> 5880 | K29: =IFERROR(H29*J29,0) -> 0 | P29: =IF(M29>=F29,M29-F29,0) -> 0 | Q29: =IF(N29+O29-G29>=0,N29+O29-G29,0) -> 0 | R29: =P29+Q29 -> 0 | S29: https://articulo.mercadolibre.cl/MLC-2855615494-fuente-de-agua-pileta-de-agua-buda-feng-shui-18-cm-con-luz-gris-_JM
A30: {=XLOOKUP(B30,Costos_Proveedores!$B$2:$B$2000,Costos_Proveedores!$A$2:$A$2000)} -> MULI | B30: MLC2855521002 | C30: 106551G | D30: Basurero Metálico Con Pedal 8 Litros Pedal Acabado Madera Color Gris | E30: paused | F30: 0 | G30: 0 | H30: =IF(I30="Sí",F30,F30+G30) -> 0 | I30: No | J30: =VLOOKUP(B30,Costos_Proveedores!$B$2:$J$1000,9,FALSE()) -> 8400 | K30: =IFERROR(H30*J30,0) -> 0 | P30: =IF(M30>=F30,M30-F30,0) -> 0 | Q30: =IF(N30+O30-G30>=0,N30+O30-G30,0) -> 0 | R30: =P30+Q30 -> 0 | S30: https://articulo.mercadolibre.cl/MLC-2855521002-basurero-metalico-con-pedal-8-litros-pedal-acabado-madera-color-gris-_JM
A31: {=XLOOKUP(B31,Costos_Proveedores!$B$2:$B$2000,Costos_Proveedores!$A$2:$A$2000)} -> MULI | B31: MLC1585279801 | C31: WF33311 | D31: Estatua Buda Pileta De Agua Fuente De Agua Buda 28cm Con Luz Gris | E31: paused | F31: 0 | G31: 0 | H31: =IF(I31="Sí",F31,F31+G31) -> 0 | I31: No | J31: =VLOOKUP(B31,Costos_Proveedores!$B$2:$J$1000,9,FALSE()) -> 12600 | K31: =IFERROR(H31*J31,0) -> 0 | P31: =IF(M31>=F31,M31-F31,0) -> 0 | Q31: =IF(N31+O31-G31>=0,N31+O31-G31,0) -> 0 | R31: =P31+Q31 -> 0 | S31: https://articulo.mercadolibre.cl/MLC-1585279801-estatua-buda-pileta-de-agua-fuente-de-agua-buda-28cm-con-luz-gris-_JM
A32: {=XLOOKUP(B32,Costos_Proveedores!$B$2:$B$2000,Costos_Proveedores!$A$2:$A$2000)} -> MULI | B32: MLC1585279683 | C32: 105651 | D32: Colgante De Viento Campana De Viento Llamador De Angel 68cm Plateado | E32: active | F32: 2 | G32: 0 | H32: =IF(I32="Sí",F32,F32+G32) -> 2 | I32: No | J32: =VLOOKUP(B32,Costos_Proveedores!$B$2:$J$1000,9,FALSE()) -> 2730 | K32: =IFERROR(H32*J32,0) -> 5460 | L32: 4 | M32: 4 | N32: 0 | O32: 0 | P32: =IF(M32>=F32,M32-F32,0) -> 2 | Q32: =IF(N32+O32-G32>=0,N32+O32-G32,0) -> 0 | R32: =P32+Q32 -> 2 | S32: https://articulo.mercadolibre.cl/MLC-1585279683-colgante-de-viento-campana-de-viento-llamador-de-angel-68cm-plateado-_JM
A33: {=XLOOKUP(B33,Costos_Proveedores!$B$2:$B$2000,Costos_Proveedores!$A$2:$A$2000)} -> MULI | B33: MLC1585189105 | C33: 105650 | D33: Colgante De Viento Campana De Viento Llamador De Angel Turco Plateado | E33: active | F33: 3 | G33: 0 | H33: =IF(I33="Sí",F33,F33+G33) -> 3 | I33: No | J33: =VLOOKUP(B33,Costos_Proveedores!$B$2:$J$1000,9,FALSE()) -> 2030 | K33: =IFERROR(H33*J33,0) -> 6090 | L33: 1 | M33: 0 | N33: 0 | O33: 1 | P33: =IF(M33>=F33,M33-F33,0) -> 0 | Q33: =IF(N33+O33-G33>=0,N33+O33-G33,0) -> 1 | R33: =P33+Q33 -> 1 | S33: https://articulo.mercadolibre.cl/MLC-1585189105-colgante-de-viento-campana-de-viento-llamador-de-angel-turco-plateado-_JM
A34: {=XLOOKUP(B34,Costos_Proveedores!$B$2:$B$2000,Costos_Proveedores!$A$2:$A$2000)} -> MULI | B34: MLC1585173079 | C34: BM22104 | D34: Figura Estatua Adorno Caballo Blanco Grande 29 Cm Elegante Blanco | E34: paused | G34: 0 | H34: =IF(I34="Sí",F34,F34+G34) -> 0 | I34: No | J34: =VLOOKUP(B34,Costos_Proveedores!$B$2:$J$1000,9,FALSE()) -> 11760 | K34: =IFERROR(H34*J34,0) -> 0 | P34: =IF(M34>=F34,M34-F34,0) -> 0 | Q34: =IF(N34+O34-G34>=0,N34+O34-G34,0) -> 0 | R34: =P34+Q34 -> 0 | S34: https://articulo.mercadolibre.cl/MLC-1585173079-figura-estatua-adorno-caballo-blanco-grande-29-cm-elegante-blanco-_JM
A35: {=XLOOKUP(B35,Costos_Proveedores!$B$2:$B$2000,Costos_Proveedores!$A$2:$A$2000)} -> MULI | B35: MLC1585111423 | C35: 107093 | D35: Caja 48 Tazones Para Sublimacion Blanco Grado A 11oz Ceramic Blanco | E35: paused | G35: 0 | H35: =IF(I35="Sí",F35,F35+G35) -> 0 | I35: No | J35: =VLOOKUP(B35,Costos_Proveedores!$B$2:$J$1000,9,FALSE()) -> 26208 | K35: =IFERROR(H35*J35,0) -> 0 | P35: =IF(M35>=F35,M35-F35,0) -> 0 | Q35: =IF(N35+O35-G35>=0,N35+O35-G35,0) -> 0 | R35: =P35+Q35 -> 0 | S35: https://articulo.mercadolibre.cl/MLC-1585111423-caja-48-tazones-para-sublimacion-blanco-grado-a-11oz-ceramic-blanco-_JM
A36: {=XLOOKUP(B36,Costos_Proveedores!$B$2:$B$2000,Costos_Proveedores!$A$2:$A$2000)} -> MULI | B36: MLC1585098747 | C36: WF33374 | D36: Estatua Decorativa Pileta De Agua Fuente De Agua Grande 40cm Gris | E36: paused | G36: 0 | H36: =IF(I36="Sí",F36,F36+G36) -> 0 | I36: No | J36: =VLOOKUP(B36,Costos_Proveedores!$B$2:$J$1000,9,FALSE()) -> 16800 | K36: =IFERROR(H36*J36,0) -> 0 | P36: =IF(M36>=F36,M36-F36,0) -> 0 | Q36: =IF(N36+O36-G36>=0,N36+O36-G36,0) -> 0 | R36: =P36+Q36 -> 0 | S36: https://articulo.mercadolibre.cl/MLC-1585098747-estatua-decorativa-pileta-de-agua-fuente-de-agua-grande-40cm-gris-_JM
A37: {=XLOOKUP(B37,Costos_Proveedores!$B$2:$B$2000,Costos_Proveedores!$A$2:$A$2000)} -> MULI | B37: MLC1585094821 | C37: 105741 | D37: Set Jarra Y 6 Vasos Conjunto Jarra 2 Litros 6 Vasos Vidrio Transparente | E37: paused | F37: 0 | G37: 0 | H37: =IF(I37="Sí",F37,F37+G37) -> 0 | I37: No | J37: =VLOOKUP(B37,Costos_Proveedores!$B$2:$J$1000,9,FALSE()) -> 7560 | K37: =IFERROR(H37*J37,0) -> 0 | L37: 3 | M37: 3 | N37: 0 | O37: 0 | P37: =IF(M37>=F37,M37-F37,0) -> 3 | Q37: =IF(N37+O37-G37>=0,N37+O37-G37,0) -> 0 | R37: =P37+Q37 -> 3 | S37: https://articulo.mercadolibre.cl/MLC-1585094821-set-jarra-y-6-vasos-conjunto-jarra-2-litros-6-vasos-vidrio-transparente-_JM
A38: {=XLOOKUP(B38,Costos_Proveedores!$B$2:$B$2000,Costos_Proveedores!$A$2:$A$2000)} -> MULI | B38: MLC1585093281 | C38: 105493 | D38: Separador De Servicios Organizador De Servicios O Cubiertos Blanco | E38: paused | F38: 0 | G38: 0 | H38: =IF(I38="Sí",F38,F38+G38) -> 0 | I38: No | J38: =VLOOKUP(B38,Costos_Proveedores!$B$2:$J$1000,9,FALSE()) -> $ 756 | K38: =IFERROR(H38*J38,0) -> 0 | L38: 25 | M38: 20 | N38: 0 | O38: 0 | P38: =IF(M38>=F38,M38-F38,0) -> 20 | Q38: =IF(N38+O38-G38>=0,N38+O38-G38,0) -> 0 | R38: =P38+Q38 -> 20 | S38: https://articulo.mercadolibre.cl/MLC-1585093281-separador-de-servicios-organizador-de-servicios-o-cubiertos-blanco-_JM
A39: {=XLOOKUP(B39,Costos_Proveedores!$B$2:$B$2000,Costos_Proveedores!$A$2:$A$2000)} -> MULI | B39: MLC2856205088 | C39: BM22183 | D39: Estatua Figura Gato Adorno Interior Gata Regalo 30 Cm Blanco | E39: paused | F39: 0 | G39: 0 | H39: =IF(I39="Sí",F39,F39+G39) -> 0 | I39: No | J39: =VLOOKUP(B39,Costos_Proveedores!$B$2:$J$1000,9,FALSE()) -> 6300 | K39: =IFERROR(H39*J39,0) -> 0 | L39: 1 | M39: 1 | N39: 0 | O39: 0 | P39: =IF(M39>=F39,M39-F39,0) -> 1 | Q39: =IF(N39+O39-G39>=0,N39+O39-G39,0) -> 0 | R39: =P39+Q39 -> 1 | S39: https://articulo.mercadolibre.cl/MLC-2856205088-estatua-figura-gato-adorno-interior-gata-regalo-30-cm-blanco-_JM
A40: {=XLOOKUP(B40,Costos_Proveedores!$B$2:$B$2000,Costos_Proveedores!$A$2:$A$2000)} -> MULI | B40: MLC2855996872 | C40: RS66888 | D40: Estatua Dama De La Justicia Adorno Dama De La Justicia Plateado | E40: paused | F40: 0 | G40: 0 | H40: =IF(I40="Sí",F40,F40+G40) -> 0 | I40: No | J40: =VLOOKUP(B40,Costos_Proveedores!$B$2:$J$1000,9,FALSE()) -> 11760 | K40: =IFERROR(H40*J40,0) -> 0 | L40: 3 | M40: 3 | N40: 0 | O40: 0 | P40: =IF(M40>=F40,M40-F40,0) -> 3 | Q40: =IF(N40+O40-G40>=0,N40+O40-G40,0) -> 0 | R40: =P40+Q40 -> 3 | S40: https://articulo.mercadolibre.cl/MLC-2855996872-estatua-dama-de-la-justicia-adorno-dama-de-la-justicia-plateado-_JM
...

Sheet Valorización
B2: Stock Declarado | C2: =SUM(Global!K2:K1011) -> 36108019
A4: STOCK NO DECLARADO
A5: STRIVE | B5: =260-52 -> 208 | C5: 14113 | D5: =B5*C5*1.19 -> 3493249.8
A6: STRIVE | B6: =260-52 -> 208 | C6: 15290 | D6: =B6*C6*1.19 -> 3784580.8
A7: STRIVE | B7: =260-52 -> 208 | C7: 15290 | D7: =B7*C7*1.19 -> 3784580.8
A8: SOMOS LOKAL | D8: 657554
A9: ZEO SPORT | D9: 2105967
A10: STRIVE | B10: 260 | D10: 5081338
B12: ACTIVOS | C12: VALORIZACION | D12: =SUM(D5:D10)+C2 -> 55015289
C13: CASH ON HAND | D13: 8303411
C14: CASH ON HAND (P) | D14: 6496096
B16: PASIVOS | C16: INFORMALES | D16: 41523355
C17: FORMALES | D17: 14389040
B19: NETO | D19: =D12+D13+D14-D16-D17 -> 13902401
B21: MENSUALIZADO | D21: =D19/9 -> 1544711.3
E22: M | F22: A | G22: Mayo | H22: Junio | I22: Julio | J22: Ag | K22: Sep | L22: Oct | M22: Nov
E23: 1 | F23: 2 | G23: 3 | H23: 4 | I23: 5 | J23: 6 | K23: 7 | L23: 8 | M23: 9 | N23: 12
E24: 300000 | F24: 2000000 | G24: 3500000 | H24: 4000000 | I24: 5000000 | J24: 5000000 | K24: 5000000 | L24: 5000000 | M24: 5000000
D25: Interes | E25: -2000000
D26: Sueldo | E26: =-170000-20000 -> -190000 | F26: =E26 -> -190000 | G26: =F26 -> -190000 | H26: =G26 -> -190000 | I26: =H26-150000 -> -340000 | J26: =I26 -> -340000 | K26: =J26-50000 -> -390000 | L26: =K26-50000 -> -440000 | M26: =L26-50000 -> -490000
D27: Muli | E27: -20000 | F27: -20000 | G27: -20000 | H27: -20000 | I27: -20000 | J27: -20000 | K27: -20000 | L27: -20000 | M27: -20000
D28: insumos | E28: -20000 | F28: -20000 | G28: -20000 | H28: -20000 | I28: -20000 | J28: -20000 | K28: -20000 | L28: -20000 | M28: -20000
D29: Chapa | F29: -150000
D30: Lavadora | G30: -420000
D31: Perruchas | L31: =-420000-690000 -> -1110000
D32: PPM | E32: -100000 | F32: -300000 | G32: -500000 | H32: -500000 | I32: -600000 | J32: -600000 | K32: -600000 | L32: -600000 | M32: -600000
D33: Neto | E33: =SUM(E24:E32) -> -2030000 | F33: =SUM(F24:F32) -> 1320000 | G33: =SUM(G24:G32) -> 2350000 | H33: =SUM(H24:H32) -> 3270000 | I33: =SUM(I24:I32) -> 4020000 | J33: =SUM(J24:J32) -> 4020000 | K33: =SUM(K24:K32) -> 3970000 | L33: =SUM(L24:L32) -> 2810000 | M33: =SUM(M24:M32) -> 3870000
D36: =SUM(E24:M24) -> 34800000 | E36: =SUM(E24:M32)+F36+G36+H36 -> 22414000 | F36: -550000 | G36: -11000 | H36: =-2500000/12*3 -> -625000
D37: =D36+E36 -> 57214000
D41: Casa Curauma | G41: -100000 | H41: -100000 | I41: -100000 | J41: -100000 | K41: -100000 | L41: -100000 | M41: -100000
D42: Casa stgo | J42: -150000 | K42: -150000 | L42: -150000 | M42: -150000

Sheet Costos_Proveedores
A1: Proveedor | B1: Número de publicación | C1: SKU | D1: Título | E1: Precio | F1: Comision % | G1: Comision $ | H1: Envio | I1: Ingreso | J1: Costo | K1: Utilidad | L1: Rentabilidad | M1: un x Caja Maestra
A2: ALMA | B2: MLC2906301858 | C2: 745853477929 | D2: Goldenmilk Tradicional 240 G Alma Golden Food - Leche Dorada | E2: $ 28,990 | F2: 0.1 | G2: $ 2,899 | H2: $ 3,100 | I2: $ 22,991 | J2: 12977 | K2: $ 10,014 | L2: 77.17% | M2: 1
A3: ALMA | B3: MLC2912910014 | C3: 745853477929 | D3: Goldenmilk Tradicional 240 G Alma Golden Food - Leche Dorada | E3: $ 19,738 | F3: 0.15 | G3: $ 2,961 | H3: $ - | I3: $ 16,777 | J3: 12977 | K3: $ 3,800 | L3: 29.28% | M3: 1
A4: ALMA | B4: MLC3009302444 | C4: Alma Matcha | D4: Goldenmilk Matcha 240 Gr - Leche Dorada Alma Foods | G4: $ - | I4: $ - | J4: 12977 | K4: $ (12,977) | L4: -100.00% | M4: 1
A5: ALMA | B5: MLC3009771438 | C5: Alma Cacao | D5: Goldenmilk Cacao 240 Gr - Leche Dorada Alma Foods | G5: $ - | I5: $ - | J5: 12977 | K5: $ (12,977) | L5: -100.00% | M5: 1
A6: ALMA | B6: MLC1726540139 | C6: Alma Matcha | D6: Goldenmilk Matcha 240 Gr - Leche Dorada Alma Foods | J6: 12977 | M6: 1
A7: BLENDS N TEA | B7: MLC2906248372 | C7: gdm100 | D7: Golden Milk 100 Gr Blends & Tea | E7: $ 11,990 | F7: 0.1 | G7: $ 2,199 | H7: $ - | I7: $ 9,791 | J7: 8033 | K7: $ 1,758 | L7: 21.88% | M7: 1
A8: BLENDS N TEA | B8: MLC2906348734 | C8: HD100 | D8: Te Hibisco Detox Vitalidad 100 Gr Blends & Tea | E8: $ 11,990 | F8: 0.15 | G8: $ 1,799 | H8: $ - | I8: $ 10,192 | J8: 8033 | K8: $ 2,159 | L8: 26.87% | M8: 1
A9: BLENDS N TEA | B9: MLC2938085790 | C9: gdm200 | D9: Golden Milk 200 gr Blends N Tea | E9: $ 19,980 | F9: 0.15 | G9: $ 2,997 | H9: $ - | I9: $ 16,983 | J9: 12054 | K9: $ 4,929 | L9: 40.90% | M9: 1
A10: BLENDS N TEA | B10: MLC2950215486 | C10: HD150 | D10: Te Hibisco Detox Vitalidad 150 Gr Blends & Tea | G10: $ - | I10: $ - | J10: 10043 | K10: $ (10,043) | L10: -100.00% | M10: 1
A11: BLENDS N TEA | B11: MLC3114523712 | C11: GDM150RG | D11: Golden Milk 150g Recarga Blends And Tea Curcuma | G11: $ - | I11: $ - | J11: 8033 | K11: $ (8,033) | L11: -100.00% | M11: 1
A12: BLENDS N TEA | B12: MLC3114447200 | C12: afm50 | D12: Infusión Armonía Fase Menstrual 50g Blends And Tea | G12: $ - | I12: $ - | J12: 6024 | K12: $ (6,024) | L12: -100.00% | M12: 1
A13: BLENDS N TEA | B13: MLC3114485416 | C13: afm150 | D13: Infusión Armonía Fase Menstrual 150g Blends And Tea | G13: $ - | I13: $ - | J13: 10042 | K13: $ (10,042) | L13: -100.00% | M13: 1
A14: BLENDS N TEA | B14: MLC3114472312 | C14: afmrg | D14: Infusión Armonía Fase Menstrual 100g Recarga | G14: $ - | I14: $ - | J14: 6694 | K14: $ (6,694) | L14: -100.00% | M14: 1
A15: BLENDS N TEA | B15: MLC3114601822 | C15: A50 | D15: Infusión Azul Relajante 50g | G15: $ - | I15: $ - | J15: 5354 | K15: $ (5,354) | L15: -100.00% | M15: 1
A16: BLENDS N TEA | B16: MLC3114549828 | C16: A100 | D16: Infusión Azul Relajante 100g Blends And Tea | G16: $ - | I16: $ - | J16: 8033 | K16: $ (8,033) | L16: -100.00% | M16: 1
A17: BLENDS N TEA | B17: MLC3114588654 | C17: A150 | D17: Infusión Azul Relajante 150g Blends And Tea | G17: $ - | I17: $ - | J17: 10042 | K17: $ (10,042) | L17: -100.00% | M17: 1
A18: BLENDS N TEA | B18: MLC3114537112 | C18: A100RG | D18: Infusión Azul Relajante 100g Recarga Blends And Tea | G18: $ - | I18: $ - | J18: 6694 | K18: $ (6,694) | L18: -100.00% | M18: 1
A19: BLENDS N TEA | B19: MLC3114472506 | C19: hsp50 | D19: Hibisco Sueño Profundo 50g Blends And Tea | G19: $ - | I19: $ - | J19: 5354 | K19: $ (5,354) | L19: -100.00% | M19: 1
A20: BLENDS N TEA | B20: MLC3114563012 | C20: hsp100 | D20: Hibisco Sueño Profundo 100g Blends And Tea | G20: $ - | I20: $ - | J20: 8033 | K20: $ (8,033) | L20: -100.00% | M20: 1
A21: BLENDS N TEA | B21: MLC3114537172 | C21: hsp150 | D21: Hibisco Sueño Profundo 150g Blends And Tea | G21: $ - | I21: $ - | J21: 10042 | K21: $ (10,042) | L21: -100.00% | M21: 1
... A75: BLENDS N TEA | B75: MLC3134950270 | C75: HD150 | D75: Te Hibisco Detox Vitalidad 150 Gr Blends & Tea | G75: $ - | I75: $ - | J75: 10043 | K75: $ (10,043) | L75: -100.00% | M75: 1
A76: BLENDS N TEA | B76: MLC1715850997 | C76: OC150 | D76: Te Oolong Manzana Canela 150g Blends And Tea | J76: 8033 | M76: 1
A77: CASO Y CIA | B77: MLC1608022999 | C77: PACK 4 710768 | D77: Pack 4 Superbot Serie 3 - Superzings Figuras Coleccionables | E77: $ 13,721 | F77: 0.16 | G77: $ 2,195 | H77: $ - | I77: $ 11,526 | J77: 6941 | K77: $ 4,585 | L77: 66.05% | M77: 1
A78: CASO Y CIA | B78: MLC2888665676 | C78: 710763 | D78: Super Zings Serie 3 - Caja Sellada 25 Personajes | E78: $ 24,240 | F78: 0.16 | G78: $ 3,878 | H78: $ 3,100 | I78: $ 17,262 | J78: 14500 | K78: $ 2,762 | L78: 19.05% | M78: 16
A79: CASO Y CIA | B79: MLC2902258430 | C79: 710798 | D79: Superzings Serie 3 Pack (comic + Superbot + 2 Fig + Slider) | E79: $ 7,990 | F79: 0.16 | G79: $ 1,278 | H79: $ - | I79: $ 6,712 | J79: 4665 | K79: $ 2,047 | L79: 43.87% | M79: 1
A80: CASO Y CIA | B80: MLC1621478293 | C80: Pack10TwoPack | D80: Pack 10 Sobres Twopack (villano + Heroe) Superzings Serie 3 | E80: $ 19,980 | F80: 0.16 | G80: $ 3,197 | H80: $ - | I80: $ 16,783 | J80: 11542 | K80: $ 5,241 | L80: 45.41% | M80: 24
A81: CASO Y CIA | B81: MLC2886979324 | C81: SOBRES 710763 | D81: Super Zings Serie 3 Pack 10 Sobres | E81: $ 10,838 | F81: 0.16 | G81: $ 2,758 | H81: $ - | I81: $ 8,080 | J81: 5800 | K81: $ 2,280 | L81: 39.31% | M81: 40
A82: CASO Y CIA | B82: MLC1607984995 | C82: 710766 | D82: 9+1 Superzings Dorado Coleccionables Superzings Serie 3 | E82: $ 15,980 | F82: 0.16 | G82: $ 2,557 | H82: $ - | I82: $ 13,423 | J82: 12094 | K82: $ 1,329 | L82: 10.99% | M82: 1
A83: CASO Y CIA | B83: MLC1607889075 | C83: 710765 | D83: Super Zings Superslider Blister 5 Figuras Serie 3 | E83: $ 11,989 | F83: 0.16 | G83: $ 1,918 | H83: $ - | I83: $ 10,071 | J83: 8793 | K83: $ 1,278 | L83: 14.53% | M83: 1
A84: CASO Y CIA | B84: MLC1607933771 | C84: SOBRES 710763 | D84: Pack 10 Sobres Superzings Figuras Coleccionables Serie 3 | E84: $ 10,525 | F84: 0.16 | G84: $ 2,684 | H84: $ - | I84: $ 7,841 | J84: 5800 | K84: $ 2,041 | L84: 35.19% | M84: 40
A85: CASO Y CIA | B85: MLC2887003786 | C85: 710765 | D85: 5 Figuras + Nave + Rampla Superzings Serie 3 Coleccionables | E85: $ 11,989 | F85: 0.16 | G85: $ 1,918 | H85: $ - | I85: $ 10,071 | J85: 8793 | K85: $ 1,278 | L85: 14.53% | M85: 1
A86: CASO Y CIA | B86: MLC1609718647 | C86: SOBRES 5 710763 | D86: Pack 5 Sobres Superzings Figuras Coleccionables Serie 3 | E86: $ 9,320 | F86: 0.16 | G86: $ 1,491 | H86: $ - | I86: $ 7,829 | J86: 3522 | K86: $ 4,307 | L86: 122.31% | M86: 1
A87: CASO Y CIA | B87: MLC2889808586 | C87: 710768 | D87: Superzings Caja 8 Superbots Figuras Coleccionables Serie 3 | E87: $ 33,311 | F87: 0.16 | G87: $ 5,330 | H87: $ 3,150 | I87: $ 24,831 | J87: 19278 | K87: $ 5,553 | L87: 28.81% | M87: 1
A88: CASO Y CIA | B88: MLC1646935669 | C88: Pack10TwoPack | D88: Pack 10 Sobres Twopack (villano + Heroe) Superzings Serie 3 | E88: $ 19,980 | F88: 0.16 | G88: $ 4,197 | H88: $ - | I88: $ 15,783 | J88: 11542 | K88: $ 4,241 | L88: 36.75% | M88: 1
A89: CASO Y CIA | B89: MLC2978633074 | C89: 710763 | D89: Super Zings Caja 25 Figuras Coleccionables Serie 3 | G89: $ - | I89: $ - | J89: 14500 | K89: $ (14,500) | L89: -100.00% | M89: 16
A90: CASO Y CIA | B90: MLC1703814075 | C90: 710837 Caja Completa Megajet | D90: Caja 8 Megajets + 8 Figuras Superzing Serie 4 | J90: 14698 | M90: 6
A91: CASO Y CIA | B91: MLC1703735977 | C91: 710837 Caja Completa Megajet | D91: Superzings Series 4 Display 8 Megajet + Figura | J91: 14698 | M91: 6
A92: CASO Y CIA | B92: MLC3174055132 | C92: 710837 Pack 4 Megajets | D92: Pack 4 Megajets + 4 Figuras Superzing Serie 4 | J92: 7349 | M92: 12
A93: CASO Y CIA | B93: MLC3173887108 | C93: 710843 Pack 5 Superjets | D93: Pack 5 Blaster Jets + 5 Figuras Superzing Serie 4 | J93: 9178 | M93: 38
...
